<?xml version='1.0'?>



<sdf version ='1.6'>

  <model name ='player'>

    <pose>0 0 0 0 0 0</pose>

    <link name ='chassi'>
      <pose>0 0 0.01 0 0 0</pose>
      <inertial>
        <pose>0 0 0.035 0 0 0</pose>
        <mass> 0.31360000000000005</mass>
        <inertia>
          <ixx>0.00029530666666666676</ixx>
          <ixy>0.000000</ixy>
          <ixz>0.000000</ixz>
          <iyy>0.00029530666666666676</iyy>
          <iyz>0.000000</iyz>
          <izz>0.00033450666666666673</izz>
        </inertia>
      </inertial>

      <collision name ='chassi_kicker_collision'>
        <geometry>
          <polyline>
            <height>0.04</height>
            <point>0.04 0.04</point>
            <point>-0.04 0.04</point>
            <point>-0.04 -0.04</point>
            <point>0.04 -0.04</point>
            
            <point>0.04 -0.024999999999999998</point>
            <point>0.038361567874263584 -0.021918557339453873</point>
            <point>0.036942077460882565 -0.0187303296707956</point>
            <point>0.035748444374464255 -0.015450849718747368</point>
            <point>0.03478648387542212 -0.012096094779983385</point>
            <point>0.03406088253861154 -0.008682408883346515</point>
            <point>0.033575175420808276 -0.005226423163382669</point>
            <point>0.03333172883826715 -0.0017449748351250453</point>
            <point>0.03333172883826715 0.001744974835125051</point>
            <point>0.033575175420808276 0.0052264231633826755</point>
            <point>0.03406088253861154 0.008682408883346518</point>
            <point>0.03478648387542212 0.012096094779983387</point>
            <point>0.03574844437446426 0.015450849718747377</point>
            <point>0.036942077460882565 0.018730329670795607</point>
            <point>0.03836156787426359 0.021918557339453873</point>
            <point>0.04 0.024999999999999998</point>
          </polyline>
        </geometry>
      </collision>

      <collision name ='chassi_body_collision'>
        <pose>0 0 0.055 0 0 0</pose>
        <geometry>
          <box><size>0.08 0.08 0.03</size></box>
        </geometry>
      </collision>

      <visual name ='chassi_kicker_visual'>
        <geometry>
          <polyline>
            <height>0.04</height>
            <point>0.04 0.04</point>
            <point>-0.04 0.04</point>
            <point>-0.04 -0.04</point>
            <point>0.04 -0.04</point>
            
            <point>0.04 -0.024999999999999998</point>
            <point>0.038361567874263584 -0.021918557339453873</point>
            <point>0.036942077460882565 -0.0187303296707956</point>
            <point>0.035748444374464255 -0.015450849718747368</point>
            <point>0.03478648387542212 -0.012096094779983385</point>
            <point>0.03406088253861154 -0.008682408883346515</point>
            <point>0.033575175420808276 -0.005226423163382669</point>
            <point>0.03333172883826715 -0.0017449748351250453</point>
            <point>0.03333172883826715 0.001744974835125051</point>
            <point>0.033575175420808276 0.0052264231633826755</point>
            <point>0.03406088253861154 0.008682408883346518</point>
            <point>0.03478648387542212 0.012096094779983387</point>
            <point>0.03574844437446426 0.015450849718747377</point>
            <point>0.036942077460882565 0.018730329670795607</point>
            <point>0.03836156787426359 0.021918557339453873</point>
            <point>0.04 0.024999999999999998</point>
          </polyline>
        </geometry>

        <material>
          <script>
            <uri>file://Scripts</uri>
            <name>VSS_player/DarkGrey</name>
          </script>
        </material>
      </visual>

      <visual name ='chassi_body_visual'>
        <pose>0 0 0.0549985 0 0 0</pose>
        <geometry>
          <box><size>0.08 0.08 0.029997</size></box>
        </geometry>

        <material>
          <script>
            <uri>file://Scripts</uri>
            <name>VSS_player/DarkGrey</name>
          </script>
        </material>
      </visual>

      <visual name ='chassi_tag_visual'>
        <pose>0 0 0.0699965 0 0 0</pose>
        <geometry>
          <box><size>0.08 0.08 7.000000000000001e-06</size></box>
        </geometry>

        <material>
          <script>
            <uri>file://Scripts</uri>
            <uri>file://Textures/VSS_tags</uri>
          </script>
        </material>

        <plugin name="texture" filename="lib_change_material.so"> </plugin>
      </visual>

    </link>

    <link name ='left_wheel'>
      <pose>-0.0155 0.033 0.016 1.5707963267948966 0 0</pose>
      <inertial>
        <mass> 0.00804247719318987</mass>
        <inertia>
          <ixx>5.81739183640734e-07</ixx>
          <ixy>0.000000</ixy>
          <ixz>0.000000</ixz>
          <iyy>5.81739183640734e-07</iyy>
          <iyz>0.000000</iyz>
          <izz>1.0294370807283034e-06</izz>
        </inertia>
      </inertial>

      <collision name ='left_wheel_collision'>
        <geometry>
          <cylinder>
            <radius>0.016</radius>
            <length>0.01</length>
          </cylinder>
        </geometry>

        <surface>
          <friction>
            <ode>
              <mu>50</mu>
              <mu2>50</mu2>
            </ode>
          </friction>
        </surface>
      </collision>

      <visual name ='left_wheel_visual'>
        <geometry>
          <cylinder>
            <radius>0.016</radius>
            <length>0.01</length>
          </cylinder>
        </geometry>

        <material>
          <script>
            <uri>file://Scripts</uri>
            <name>VSS_player/DarkGrey</name>
          </script>
        </material>
      </visual>
    </link>

    <link name ='right_wheel'>
      <pose>-0.0155 -0.033 0.016 1.5707963267948966 0 0</pose>
      <inertial>
        <mass> 0.00804247719318987</mass>
        <inertia>
          <ixx>5.81739183640734e-07</ixx>
          <ixy>0.000000</ixy>
          <ixz>0.000000</ixz>
          <iyy>5.81739183640734e-07</iyy>
          <iyz>0.000000</iyz>
          <izz>1.0294370807283034e-06</izz>
        </inertia>
      </inertial>

      <collision name ='right_wheel_collision'>
        <geometry>
          <cylinder>
            <radius>0.016</radius>
            <length>0.01</length>
          </cylinder>
        </geometry>

        <surface>
          <friction>
            <ode>
              <mu>50</mu>
              <mu2>50</mu2>
            </ode>
          </friction>
        </surface>
      </collision>

      <visual name ='right_wheel_visual'>
        <geometry>
          <cylinder>
            <radius>0.016</radius>
            <length>0.01</length>
          </cylinder>
        </geometry>

        <material>
          <script>
            <uri>file://Scripts</uri>
            <name>VSS_player/DarkGrey</name>
          </script>
        </material>
      </visual>
    </link>

    <link name ='ball_wheel'>
      <pose>0.02 0 0.01 0 0 0</pose>
      <inertial>
        <mass> 0.004188790204786391</mass>
        <inertia>
          <ixx>1.6755160819145565e-07</ixx>
          <ixy>0.000000</ixy>
          <ixz>0.000000</ixz>
          <iyy>1.6755160819145565e-07</iyy>
          <iyz>0.000000</iyz>
          <izz>1.6755160819145565e-07</izz>
        </inertia>
      </inertial>

      <collision name ='ball_wheel_collision'>
        <geometry>
          <sphere><radius>0.01</radius></sphere>
        </geometry>

        <surface>
          <friction>
            <ode>
              <mu>1</mu>
              <mu2>1</mu2>
            </ode>
          </friction>
        </surface>
      </collision>

      <visual name ='ball_wheel_visual'>
        <geometry>
          <sphere><radius>0.01</radius></sphere>
        </geometry>

        <material>
          <script>
            <uri>file://Scripts</uri>
            <name>VSS_player/DarkGrey</name>
          </script>
        </material>
      </visual>
    </link>

    <joint name="chassi_left_wheel" type="revolute">
      <parent>chassi</parent>
      <child>left_wheel</child>
      <axis>
        <xyz>0 0 -1</xyz>
      </axis>

    </joint>

    <joint name="chassi_right_wheel" type="revolute">
      <parent>chassi</parent>
      <child>right_wheel</child>
      <axis>
        <xyz>0 0 -1</xyz>
      </axis>
    </joint>

    <joint name="chassi_ball_wheel" type="ball">
      <parent>chassi</parent>
      <child>ball_wheel</child>
    </joint>

  </model>

</sdf>
