<?xml version='1.0'?>



<sdf version ='1.6'>

  <model name ='player'>

    <pose>0 0 0 0 0 0</pose>

    <link name ='chassi'>
      <pose>0 0 0.01 0 0 0</pose>
      <inertial>
        <pose>0 0 0.035 0 0 0</pose>
        <mass> 0.31360000000000005</mass>
        <inertia>
          <ixx>0.00029530666666666676</ixx>
          <ixy>0.000000</ixy>
          <ixz>0.000000</ixz>
          <iyy>0.00029530666666666676</iyy>
          <iyz>0.000000</iyz>
          <izz>0.00033450666666666673</izz>
        </inertia>
      </inertial>

      <collision name ='chassi_kicker_collision'>
        <geometry>
          <polyline>
            <height>0.04</height>
            <point>0.04 0.04</point>
            <point>-0.04 0.04</point>
            <point>-0.04 -0.04</point>
            <point>0.04 -0.04</point>
            <point> 0.032 0</point>
          </polyline>
        </geometry>
      </collision>

      <collision name ='chassi_body_collision'>
        <pose>0 0 0.055 0 0 0</pose>
        <geometry>
          <box><size>0.08 0.08 0.03</size></box>
        </geometry>
      </collision>

      <visual name ='chassi_kicker_visual'>
        <geometry>
          <polyline>
            <height>0.04</height>
            <point>0.04 0.04</point>
            <point>-0.04 0.04</point>
            <point>-0.04 -0.04</point>
            <point>0.04 -0.04</point>
            <point> 0.032 0</point>
          </polyline>
        </geometry>

        <material>
          <script>
            <uri>file://Scripts</uri>
            <name>VSS_Player/DarkGrey</name>
          </script>
        </material>
      </visual>

      <visual name ='chassi_body_visual'>
        <pose>0 0 0.0549985 0 0 0</pose>
        <geometry>
          <box><size>0.08 0.08 0.029997</size></box>
        </geometry>

        <material>
          <script>
            <uri>file://Scripts</uri>
            <name>VSS_Player/DarkGrey</name>
          </script>
        </material>
      </visual>

      <visual name ='chassi_tag_visual'>
        <pose>0 0 0.0699965 0 0 0</pose>
        <geometry>
          <box><size>0.08 0.08 7.000000000000001e-06</size></box>
        </geometry>

        <material>
          <script>
            <uri>file://Scripts</uri>
            <uri>file://Textures/VSS</uri>
          </script>
        </material>

        <plugin name="texture" filename="libchange_texture.so"> </plugin>
      </visual>

    </link>

    <link name ='left_wheel'>
      <pose>-0.0155 0.033 0.016 1.570796 0 0</pose>
      <inertial>
        <mass> 0.00402123776</mass>
        <inertia>
          <ixx>2.908695313066667e-07</ixx>
          <ixy>0.000000</ixy>
          <ixz>0.000000</ixz>
          <iyy>2.908695313066667e-07</iyy>
          <iyz>0.000000</iyz>
          <izz>5.1471843328e-07</izz>
        </inertia>
      </inertial>

      <collision name ='left_wheel_collision'>
        <geometry>
          <cylinder>
            <radius>0.016</radius>
            <length>0.01</length>
          </cylinder>
        </geometry>

        <surface>
          <friction>
            <ode>
              <mu>50</mu>
              <mu2>50</mu2>
            </ode>
          </friction>
        </surface>
      </collision>

      <visual name ='left_wheel_visual'>
        <geometry>
          <cylinder>
            <radius>0.016</radius>
            <length>0.01</length>
          </cylinder>
        </geometry>

        <material>
          <script>
            <uri>file://Scripts</uri>
            <name>VSS_Player/DarkGrey</name>
          </script>
        </material>
      </visual>
    </link>

    <link name ='right_wheel'>
      <pose>-0.0155 -0.033 0.016 1.570796 0 0</pose>
      <inertial>
        <mass> 0.00402123776</mass>
        <inertia>
          <ixx>2.908695313066667e-07</ixx>
          <ixy>0.000000</ixy>
          <ixz>0.000000</ixz>
          <iyy>2.908695313066667e-07</iyy>
          <iyz>0.000000</iyz>
          <izz>5.1471843328e-07</izz>
        </inertia>
      </inertial>

      <collision name ='right_wheel_collision'>
        <geometry>
          <cylinder>
            <radius>0.016</radius>
            <length>0.01</length>
          </cylinder>
        </geometry>

        <surface>
          <friction>
            <ode>
              <mu>50</mu>
              <mu2>50</mu2>
            </ode>
          </friction>
        </surface>
      </collision>

      <visual name ='right_wheel_visual'>
        <geometry>
          <cylinder>
            <radius>0.016</radius>
            <length>0.01</length>
          </cylinder>
        </geometry>

        <material>
          <script>
            <uri>file://Scripts</uri>
            <name>VSS_Player/DarkGrey</name>
          </script>
        </material>
      </visual>
    </link>

    <link name ='ball_wheel'>
      <pose>0.02 0 0.01 0 0 0</pose>
      <inertial>
        <mass> 0.002094394666666667</mass>
        <inertia>
          <ixx>8.377578666666668e-08</ixx>
          <ixy>0.000000</ixy>
          <ixz>0.000000</ixz>
          <iyy>8.377578666666668e-08</iyy>
          <iyz>0.000000</iyz>
          <izz>8.377578666666668e-08</izz>
        </inertia>
      </inertial>

      <collision name ='ball_wheel_collision'>
        <geometry>
          <sphere><radius>0.01</radius></sphere>
        </geometry>

        <surface>
          <friction>
            <ode>
              <mu>1</mu>
              <mu2>1</mu2>
            </ode>
          </friction>
        </surface>
      </collision>

      <visual name ='ball_wheel_visual'>
        <geometry>
          <sphere><radius>0.01</radius></sphere>
        </geometry>

        <material>
          <script>
            <uri>file://Scripts</uri>
            <name>VSS_Player/DarkGrey</name>
          </script>
        </material>
      </visual>
    </link>

    <joint name="chassi_left_wheel" type="revolute">
      <parent>chassi</parent>
      <child>left_wheel</child>
      <axis>
        <xyz>0 0 -1</xyz>
      </axis>

    </joint>

    <joint name="chassi_right_wheel" type="revolute">
      <parent>chassi</parent>
      <child>right_wheel</child>
      <axis>
        <xyz>0 0 -1</xyz>
      </axis>
    </joint>

    <joint name="chassi_ball_wheel" type="ball">
      <parent>chassi</parent>
      <child>ball_wheel</child>
    </joint>

  </model>

</sdf>
